Workbook
Name Funcionarios: Tabela10[]
Name Funcionarios: Tabela10[]
Name Funcionarios: Tabela10[]
Name Setores: Setor!#REF!

Sheet Menu

Sheet Funcionários
B4: Funcionários | C4: Setor
B5: JOÃO BUTZKE | C5: =_xlfn.CONCAT(Setor!B7) -> INTELIGENCIA DE REDES
B6: FELIPE FOLSTER | C6: =_xlfn.CONCAT(Setor!B7) -> INTELIGENCIA DE REDES
B7: GUILHERME VASCONCELLOS BARDALHO | C7: =_xlfn.CONCAT(Tabela1[[#This Row],[Setores]]) -> INTELIGENCIA DE REDES
B8: MANOEL IAGO SOUZA DOS SANTOS | C8: =_xlfn.CONCAT(Setor!B7) -> INTELIGENCIA DE REDES
B9: LUIZA CUNHA SENA | C9: =_xlfn.CONCAT(Setor!B10) -> AGILIDADE
B10: VINICIUS COELHO | C10: =_xlfn.CONCAT(Setor!B10) -> AGILIDADE
B11: ISRAEL FELIX | C11: MARKETING
B12: CAIO EDUARDO SIQUEIRA DA SILVA | C12: =_xlfn.CONCAT(Setor!B7) -> INTELIGENCIA DE REDES
B13: JAKSON WEINGARTNER | C13: =_xlfn.CONCAT(Setor!B7) -> INTELIGENCIA DE REDES
B14: SAMUEL RIBEIRO | C14: =_xlfn.CONCAT(Setor!B11) -> INTELIGENCIA DE DADOS
B15: EDILAINE ANTUNES | C15: =_xlfn.CONCAT(Setor!B5) -> RELACIONAMENTO COM O CLIENTE
B16: ANA CARLA DA ROSA GODINHO | C16: =_xlfn.CONCAT(Setor!B8) -> FINANCEIRO
B17: LARISSA MAY BACK | C17: =_xlfn.CONCAT(Setor!B8) -> FINANCEIRO
B18: LUANA BORGES BATISTA | C18: =_xlfn.CONCAT(Setor!B8) -> FINANCEIRO
B19: GRAZIELLY MACEDO | C19: =_xlfn.CONCAT(Setor!B8) -> FINANCEIRO
B20: LUCAS MOURA DA SILVA | C20: =_xlfn.CONCAT(Setor!B9) -> COMERCIAL
B21: MILENE CRISTINA DA SILVA | C21: FINANCEIRO
B22: AMANDA ISSLER NERY | C22: =_xlfn.CONCAT(Setor!B9) -> COMERCIAL
B23: CLEYLSON DA SILVA PIMENTEL | C23: =_xlfn.CONCAT(Setor!B9) -> COMERCIAL
B24: VITOR ADRIANO COELHO | C24: =_xlfn.CONCAT(Setor!B9) -> COMERCIAL
B25: MIHAY FERREIRA | C25: =_xlfn.CONCAT(Setor!B9) -> COMERCIAL
B26: JULIO CESAR DA SILVA | C26: COMERCIAL
B27: TAIS PAIM | C27: =_xlfn.CONCAT(Setor!B9) -> COMERCIAL
B28: VANDERLEI MANENTTI SCOTT | C28: CTO
B29: EVERSON KLEBER MAI | C29: CEO
B30: CAROLINE FOGAÇA DA ROCHA | C30: =_xlfn.CONCAT(Setor!B12) -> EXPERIENCIA DAS PESSOAS
B31: LETICIA EMANUELE DE OLIVEIRA | C31: =_xlfn.CONCAT(Setor!B12) -> EXPERIENCIA DAS PESSOAS
B32: ANTONIO JOAO MARCELINO | C32: =_xlfn.CONCAT(Setor!B13) -> GESTÃO DE FORNECEDORES
B33: ALCIDES DOS SANTOS | C33: =_xlfn.CONCAT(Setor!B13) -> GESTÃO DE FORNECEDORES
B34: CAUAN SILVA DOS SANTOS | C34: =_xlfn.CONCAT(Setor!B13) -> GESTÃO DE FORNECEDORES
B35: WILLIAN RIBEIRO DE SOUZA | C35: =_xlfn.CONCAT(Setor!B13) -> GESTÃO DE FORNECEDORES
B36: AMANDA NEVES DE BARROS | C36: =_xlfn.CONCAT(Setor!B5) -> RELACIONAMENTO COM O CLIENTE
B37: ANA CAROLINA ALVES DAS CHAGAS | C37: =_xlfn.CONCAT(Setor!B5) -> RELACIONAMENTO COM O CLIENTE
B38: MARIANI PIERRI | C38: =_xlfn.CONCAT(Setor!B5) -> RELACIONAMENTO COM O CLIENTE
B39: EDUARDO OLIVEIRA | C39: =_xlfn.CONCAT(Setor!B5) -> RELACIONAMENTO COM O CLIENTE
B40: ANA LUIZA MATTIA DE LIMA | C40: =_xlfn.CONCAT(Setor!B11) -> INTELIGENCIA DE DADOS
B41: KLEBER COELHO | C41: =_xlfn.CONCAT(Setor!B11) -> INTELIGENCIA DE DADOS
B42: BIANCA OTON GOMES DA SILVA | C42: =_xlfn.CONCAT(Setor!B5) -> RELACIONAMENTO COM O CLIENTE
B43: NICOLLY SANTIAGO | C43: =_xlfn.CONCAT(Setor!B5) -> RELACIONAMENTO COM O CLIENTE
...

Sheet Entregues por Função
A1: Setor | B1: Função | C1: Lider | D1: Equipamentos
A2: Experiência das Pessoas | B2: Auxiliar de Limpeza | C2: Leticia | D2: Não recebe.
A3: Inovação e Desenvolvimento | B3: Desenvolvedor Back-End Junior | C3: Samuel | D3: Notebook com no mínimo: Intel Core i5 de 12ª Geração (ou equivalente), memória RAM de 16 GB e armazenamento SSD de 500 GB; Monitor adicional de 27 polegadas; Headset com microfone, com fones cobrindo ambos os ouvidos; Periféricos: Teclado e mouse.
A4: Inovação e Desenvolvimento | B4: Desenvolvedor Front-End Junior | C4: Samuel | D4: Notebook com no mínimo: Intel Core i5 de 12ª Geração (ou equivalente), memória RAM de 16 GB e armazenamento SSD de 500 GB; Monitor adicional de 27 polegadas; Headset com microfone, com fones cobrindo ambos os ouvidos; Periféricos: Teclado e mouse.
A5: NOC | B5: Assistente de Redes | C5: João | D5: Kit Teclado e mouse,headset, suporte, notebook Ryzen 5 ou Core i5 16GB 256GB SSD + Adaptador de rede caso notebook não tenha entrada RJ45, mousepad, Monitor 24" FHD Smartphone Samsumg A15 / Xiaomi Redmi 13C
A6: Relacionamento com o Cliente | B6: Atendente | C6: Emanuela | D6: Notebook, headset, teclado,mouse,suporte para notebook, mousepad
A7: Relacionamento com o Cliente | B7: Jovem Aprendiz | C7: Emanuela | D7: Notebook, headset, teclado,mouse,suporte para notebook, mousepad
A8: Suporte Externo | B8: Técnico de Suporte | C8: Bruno | D8: Celular e Chip
A9: Suporte Externo | B9: Supervisor Operacional | C9: Bruno | D9: Notebook, headset, teclado,mouse,suporte para notebook, suporte notebook, mousepad
A10: Suporte Externo | B10: Assistente de Operações | C10: Bruno | D10: Notebook, headset, teclado,mouse,suporte para notebook, suporte notebook, mousepad
A11: Suporte Externo | B11: Analista de Agendamento | C11: Bruno | D11: Notebook, headset, teclado,mouse,suporte para notebook, suporte notebook, mousepad
A12: TI | B12: Estagiário | C12: João | D12: Kit Teclado mouse,headset, suporte notebook Ryzen 5 ou Core i5/16GB RAM/256GB SSD + Adaptador de rede caso notebook não tenha entrada J45mousepad,Monitor 24" FHD E Celular Smartphone Samsumg A15 / Xiaomi Remdi 13C
A13: INFRA | B13: Técnico | C13: Jakson | D13: Celular, Chip

Sheet Setor
B4: Setores
B5: RELACIONAMENTO COM O CLIENTE
B6: INFRA
B7: INTELIGENCIA DE REDES
B8: FINANCEIRO
B9: COMERCIAL
B10: AGILIDADE
B11: INTELIGENCIA DE DADOS
B12: EXPERIENCIA DAS PESSOAS
B13: GESTÃO DE FORNECEDORES
B14: MARKETING
B15: COORDENADOR
... B18: SUPORTE NX

Sheet Equipamentos
A4: Tipo do Item | B4: Marca | C4: Modelo | D4: Serial Number | E4: Responsável | F4: Setor | G4: Patrimonio | H4: Observações
A5: All in one | B5: Samsung | C5: DP500A2L-KW1BR | E5: =_xlfn.CONCAT(Funcionários!B49) -> EDUARDA VIEIRA | F5: =_xlfn.CONCAT(Funcionários!C49) -> RELACIONAMENTO COM O CLIENTE | G5: 6164 | H5: senhas adm: m@ster2025 / N@boT3mpErad0
A6: All in one | B6: Samsung | C6: DP500A2L-KW1BR | D6: 07CH9QCH800840 | E6: =_xlfn.CONCAT(Funcionários!B126) -> HAKEEN | F6: =_xlfn.CONCAT(Setor!B12) -> EXPERIENCIA DAS PESSOAS | G6: 6159
A7: ALL IN ONE | B7: Samsung | C7: DP500A2L-KW1BR | E7: =_xlfn.CONCAT(Funcionários!B44) -> DAVI APPELT DE SÁ SARTORI | F7: =_xlfn.CONCAT(Setor!B5) -> RELACIONAMENTO COM O CLIENTE | G7: 6166
A8: Smartphone | B8: Xiaomi | C8: Redmi 9 | D8: IMEI (1) 864977059399224 | E8: =_xlfn.CONCAT(Funcionários!B150) -> MATHEUS ANDRADE | F8: =_xlfn.CONCAT(Funcionários!C150) -> RELACIONAMENTO COM O CLIENTE | G8: 28757
A9: Smartphone | B9: Xiaomi | C9: M1906G7G | G9: 31894 | H9: celularesmaisinternet@gmail.com / capivara123 / Bruno Jose / descartado
A10: Smartphone | B10: Xiaomi | C10: Redmi 12C | D10: IMEI(1) 860932063275559 | E10: =_xlfn.CONCAT(Funcionários!B90) -> VITOR PEREIRA DOS SANTOS | F10: =_xlfn.CONCAT(Funcionários!C90) -> RELACIONAMENTO COM O CLIENTE | G10: 40393 | H10: celularesmaisinternet@gmail.com / capivara123 / voltou do paolo
A11: Smartphone | B11: ASUS | C11: Zenfone Shot Plus | D11: L5AXB6008501P8K | E11: =_xlfn.CONCAT(Funcionários!B84) -> RAKELI VIEIRA | F11: =_xlfn.CONCAT(Funcionários!C84) -> RELACIONAMENTO COM O CLIENTE | G11: 37765
A12: Smartphone | B12: ASUS | C12: Zenfone Shot Plus | D12: L6AXB601D444ZAF | E12: ARMARIO | G12: 37762 | H12: celularesmaisinternet@gmail.com / capivara123 / Celular novo estava com ronald gaveta
A13: Smartphone | B13: ASUS | C13: Zenfone Shot Plus | G13: 33986 | H13: celularesmaisinternet@gmail.com / capivara123 / armário / maisinternetfibraa@gmail.com Soumais*2023
A14: GIMBAL | B14: - | C14: - | D14: - | E14: =_xlfn.CONCAT(Funcionários!B11) -> ISRAEL FELIX | F14: =_xlfn.CONCAT(Funcionários!C11) -> MARKETING | G14: 42449
A15: Monitor | B15: LG | C15: ? | D15: ? | E15: =_xlfn.CONCAT(Funcionários!B52) -> FERNANDA SILVA CONRADO | F15: =_xlfn.CONCAT(Funcionários!C43) -> RELACIONAMENTO COM O CLIENTE | G15: 32879
A16: Impressora | B16: Samsung | C16: M4070FR | D16: BRB7L5H6TY | E16: SALAO SEDE | F16: SALÃO | G16: 28155 | H16: impressaomaisinternet@gmail.com senha: capivara123 / / / / admin capivara tonner Mlt-d203u 84:25:19:1D:E4:90
A17: Impressora | B17: Epson | C17: L3150 | E17: SALA FINANCEIRO | F17: FINANCEIRO | H17: MAC 50:57:9C:88:59:19
A18: Impressora | B18: Epson | C18: L375 | E18: LOJA ZOOM | H18: 44:D2:44:0D:9B:94
A19: Impressora | B19: Epson | C19: L5190 | D19: X5NR009874 | E19: LOJA ILHA | F19: RELACIONAMENTO COM O CLIENTE | H19: 50:57:9C:92:18:BF /// Senha Acesso K@a(lo*s(%
A20: Impressora | B20: HP | C20: M1132 MFP | D20: BRCHB7V4HW | E20: TI | F20: TI | G20: 31851 | H20: Instalado no Setor NOC
A21: Impressora | B21: Brother | C21: DCP-1617NW | D21: U63980-C3X449636 | E21: LOJA SANTO AMARO | F21: UNIDADE SERRA | G21: 56616 | H21: MAC LAN: B4:22:00:C4:00:27 Senha acesso uNTt80%0
A22: Impressora | B22: Brother | C22: DCP-1610NW | D22: 63980B5L309727 | E22: LOJA BARRA DA LAGOA | F22: UNIDADE ILHA | G22: 57264 | H22: MAC WLAN: 04:68:74:9c:a3:bb MAC LAN 94:dd:f8:5e:94:b2 senha 2FHjd68G
A23: Impressora | B23: Brother | C23: DCP-L5512DN | D23: U67030B6N603233 | E23: SEDE | F23: SEDE | G23: 58859 | H23: MAC: 94-DD-F8-E4-B9-34
A24: Impressora | B24: Brother | C24: DCP-1617NW | D24: U63980-G3X602190 | E24: LOJA GAROPABA | F24: UNIDADE GAROPABA | G24: 39650 | H24: MAC LAN B4:22:00:DC:72:2C MAC WLAN CC:5E:F8:6C:AD:29 Senha acesso @n@#XGtM
A25: MiniPC | B25: Belink | C25: T4PRO | D25: B33503KH60639 | E25: TV COMERCIAL | F25: =_xlfn.CONCAT(Setor!B9) -> COMERCIAL | G25: 40037
A26: Monitor | B26: LG | C26: 27MS500-B | D26: 502AZQV4L356 | E26: =_xlfn.CONCAT(Funcionários!B40) -> ANA LUIZA MATTIA DE LIMA | F26: =_xlfn.CONCAT(Setor!B7) -> INTELIGENCIA DE REDES | G26: 49177 | H26: EQUIPAMENTO NOVO
A27: Monitor | B27: LG | C27: 27MS500-B | D27: 502AZSP4L310 | E27: =_xlfn.CONCAT(Funcionários!B41) -> KLEBER COELHO | F27: =_xlfn.CONCAT(Setor!B7) -> INTELIGENCIA DE REDES | G27: 49196 | H27: EQUIPAMENTO NOVO
A28: Monitor | B28: LG | C28: 24MS500-B | D28: 409AZMG04979 | E28: =_xlfn.CONCAT(Funcionários!B30) -> CAROLINE FOGAÇA DA ROCHA | F28: =_xlfn.CONCAT(Setor!B12) -> EXPERIENCIA DAS PESSOAS | G28: 49197
A29: Monitor | B29: LG | C29: 24MS500-B | D29: 412AZQV5Y332 | E29: =_xlfn.CONCAT(Funcionários!B47) -> MANUELLA GUIMARÃES | G29: 49192
A30: Monitor | B30: LG | C30: 24MS500-B | D30: 412AZWS6A865 | E30: =_xlfn.CONCAT(Funcionários!B65) -> JAQUELINE FREITAS JACQUES | F30: =_xlfn.CONCAT(Setor!B5) -> RELACIONAMENTO COM O CLIENTE | G30: 49175
A31: Monitor | B31: LG | C31: 26WQ500-B | D31: 404AZMGCL459 | E31: =_xlfn.CONCAT(Funcionários!B28) -> VANDERLEI MANENTTI SCOTT | F31: =_xlfn.CONCAT(Funcionários!C28) -> CTO | G31: 44920 | H31: Equipamento entregue novo
A32: Monitor | B32: LG | C32: 26WQ500-B | D32: 308AZMG9V019 | E32: EVERSON | F32: CEO | G32: 40396 | H32: Everson e Bruna
A33: Monitor | B33: LG | C33: 26WQ500-B | D33: 308AZFM9V003 | E33: EVERSON | F33: CEO | G33: 40398 | H33: Everson e Bruna
A34: Monitor | B34: LG | C34: 26WQ500-B | D34: 308AZPU67088 | E34: BRUNA | F34: CFO | G34: 40397 | H34: Everson e Bruna
A35: Monitor | B35: LG | C35: 26WQ500-B | D35: 308AZUJ67030 | E35: BRUNA | F35: CFO | G35: 40386 | H35: Everson e Bruna
A36: Monitor | B36: LG | C36: 24MK430H-B | D36: 106SPJP1M996 | E36: =_xlfn.CONCAT(Funcionários!B13) -> JAKSON WEINGARTNER | F36: =_xlfn.CONCAT(Setor!B7) -> INTELIGENCIA DE REDES | G36: 26037
A37: Monitor | B37: LG | C37: 24MP400-B | D37: 308AZYE4Q322 | E37: =_xlfn.CONCAT(Funcionários!B21) -> MILENE CRISTINA DA SILVA | F37: =_xlfn.CONCAT(Funcionários!C21) -> FINANCEIRO | G37: 40483
A38: Monitor | B38: LG | C38: 24MP400-B | D38: 308AZUJ4P846 | E38: =_xlfn.CONCAT(Funcionários!B122) -> TATIANE BORGES DE RESENDE | F38: =_xlfn.CONCAT(Funcionários!C122) -> COMERCIAL | G38: 40382 | H38: Equipamento entregue novo
A39: Monitor | B39: LENOVO | C39: S22-E19 | D39: VA769775 | E39: =_xlfn.CONCAT(Funcionários!B36) -> AMANDA NEVES DE BARROS | F39: =_xlfn.CONCAT(Funcionários!C36) -> RELACIONAMENTO COM O CLIENTE | G39: 40182
A40: Monitor | B40: LENOVO | C40: S22-E19 | D40: VA769052 | E40: =_xlfn.CONCAT(Funcionários!B35) -> WILLIAN RIBEIRO DE SOUZA | F40: =_xlfn.CONCAT(Funcionários!C35) -> GESTÃO DE FORNECEDORES | G40: 40181
A41: Monitor | B41: LENOVO | C41: S22-E19 | D41: VA769050 | E41: =_xlfn.CONCAT(Funcionários!B54) -> GABRIEL DA SILVA DIAS | F41: =_xlfn.CONCAT(Funcionários!C54) -> RELACIONAMENTO COM O CLIENTE | G41: 40038
A42: Monitor | B42: LG | C42: 24MP400 | D42: 312AZKA1H365 | E42: =_xlfn.CONCAT(Funcionários!B5) -> JOÃO BUTZKE | F42: =_xlfn.CONCAT(Funcionários!C5) -> INTELIGENCIA DE REDES | G42: 42138 | H42: Equipamento entregue novo
A43: Monitor | B43: LG | C43: 20MK400H-B | D43: 201AZERA2388 | E43: =_xlfn.CONCAT(Funcionários!B148) -> RAFAELA DILL DA SILVA | F43: =_xlfn.CONCAT(Funcionários!C148) -> RELACIONAMENTO COM O CLIENTE | G43: 28180
...

Sheet Sinistros de Equipamentos
A1: Equipamento | B1: Marca | C1: Modelo | D1: Serial | E1: Patrimonio | F1: Ocorrencia | G1: Responsavel
A2: Notebook | B2: Dell | C2: Latitude E6320 | D2: BGV69R1 | E2: SUBSTITUIDO PELO PATR. 28787 | F2: SUBSTITUIDO PELO PATR. 28787 | G2: Garantia
A3: Notebook | B3: Dell | C3: Latitude E6320 | D3: 9F9D2V1 | E3: SUBSTITUIDO PELO PATR. 28769 | F3: SUBSTITUIDO PELO PATR. 28769 | G3: Garantia
A4: Notebook | B4: Dell | C4: Latitude E6320 | E4: 27506 | F4: Molhou o notebook rep. Alex Sander | G4: Alex Sander
A5: Notebook | B5: Dell | C5: Latitude E6320 | E5: 28762 | F5: Perdeu carregador RESP JOAO RICARDO | G5: Joao Ricardo
A6: Notebook | B6: Dell | C6: Latitude E6320 | F6: Perdeu notebook resp Igor Ninoff | G6: Igor Ninoff
A7: Notebook | B7: Dell | C7: Latitude E6320 | E7: 27502 | F7: FURTADO, TEM B.O, RESP. DURVAL | G7: Durval Neto
A8: Smartphone | B8: XIAOMI | C8: M2004J19G | D8: ROUBADO | E8: 28765 | F8: Roubado resp Durval | G8: Durval Neto
A9: Smartphone | B9: XIAOMI | C9: M1908C3JG | E9: 28766 | F9: Esquecido no UBER | G9: Larissa May
A10: Telefone Voip | B10: Intelbras | C10: TIP1251 | D10: LL4G440025001 | E10: 28198 | F10: Devolvido ao estoque | G10: Estoque
A11: Telefone Voip | B11: Intelbras | C11: TIP1251 | D11: MEAG5000039VK | E11: 28162 | F11: Devolvido ao estoque | G11: Estoque
A12: Telefone Voip | B12: Intelbras | C12: TIP1251 | D12: MEAG5000062Y9 | E12: 26036 | F12: Devolvido ao estoque | G12: Estoque
A13: Telefone Voip | B13: Intelbras | C13: TIP125i | D13: MEAG500006170 | E13: 28795 | F13: Devolvido ao estoque | G13: Estoque
A14: Telefone Voip | B14: Intelbras | C14: TIP1251 | D14: MEAG500064SF | E14: 28183 | F14: Devolvido ao estoque | G14: Estoque
A15: Monitor | B15: LG | C15: L1918S | D15: 704TPFX34611 | E15: 28179 | F15: peça defeituosa | G15: Estoque
A16: Telefone Voip | B16: Intelbras | C16: TIP125 | D16: LL4G4400397D8 | E16: 30737 | F16: não liga | G16: Estoque
A17: Telefone Voip | B17: Intelbras | C17: TIP125I | D17: MEAI3000537NX | E17: 28193 | F17: Não Liga | G17: Estoque
A18: Telefone Voip | B18: Intelbras | C18: TIP125i | D18: MEAI30005551L | E18: 28181 | F18: Desmontado para doação de peças | G18: Felipe
A19: Monitor | B19: LG | C19: L1752S | D19: 608SPRW61326 | E19: 21187 | F19: Não atende requisitos para trabalho, estoque | G19: Estoque
A20: Smartphone | B20: Xiaomi | C20: M1908C3JH | E20: 31852 | F20: Tela quebrou, usado para reposição de peças | G20: Sandro Bogish
A21: Notebook | B21: Lenovo | C21: G400S | D21: 80AC000FBR | E21: 28780 | F21: Não atende requisitos para trabalho, estoque | G21: Felipe
A22: Celular | B22: ASUS | C22: Zenfone Shot Plus | E22: 31898 | F22: Aparelho extraviado | G22: Matheus Barbosa do Nascimento
A23: Notebook | B23: Dell | C23: Latitude E6320 | D23: 85M19S1 | E23: 27501 | F23: Doador de Peças | G23: Armário / Bruno Ricardo
A24: Notebook | B24: Positivo | C24: S14BW01 | D24: 4A4142K5L | E24: 5109 | F24: Não atende requisitos para trabalho, estoque | G24: Felipe
A25: Smartphone | B25: LG | C25: K41 | D25: 103BSJA1334396 | E25: 28758 | F25: Aparelho obsoleto | G25: Felipe
A26: ALL IN ONE | B26: POSITIVO | C26: UNION UD3553 | D26: 4A197BR2H | E26: 6160 | F26: PC não atende aos requisitos de Hardware para empresa | G26: Felipe
A27: Smartphone | B27: XIAOMI | C27: M1908C3JG | E27: 28764 | F27: Tela com defeito no TOUCH / celularesmaisinternet@gmail.com / capivara123 / CARREGADOR NOVO | G27: Ronald
A28: Notebook | B28: Lenovo | C28: Idepad 3 15ITL6 | D28: PE0BSSMC | E28: 40395 | F28: Notebook roubado | G28: Eduardo Oliveira
A29: ThinClient | B29: ZeroClient | C29: R1 | E29: 28191 | F29: desativado | G29: desativado
A30: ThinClient | B30: ZeroClient | C30: R1 | E30: 28164 | F30: desativado | G30: desativado
A31: ThinClient | B31: ZeroClient | C31: R1 | E31: 28169 | F31: desativado | G31: desativado
A32: ThinClient | B32: ZeroClient | C32: R1 | E32: 28188 | F32: desativado | G32: desativado
A33: ThinClient | B33: ZeroClient | C33: R1 | E33: 28774 | F33: desativado | G33: desativado
A34: ThinClient | B34: ZeroClient | C34: R1 | E34: 28797 | F34: desativado | G34: desativado
A35: ThinClient | B35: ZeroClient | C35: R1 | E35: 28736 | F35: desativado | G35: desativado
A36: Smartphone | B36: XIAOMI | C36: M1908C3JG | E36: 28763 | F36: Desativado, no estoque | G36: Felipe
A37: Smartphone | B37: LG | C37: K41S | D37: 105BSVL1517607 | E37: 31893 | F37: Desativado, no estoque | G37: Felipe
A38: Smartphone | B38: XIAOMI | C38: M1908C3JH | E38: 28761 | F38: Celular Perdido, descontado na saida | G38: Vinicius Manes
A39: All in One | B39: LG | C39: 22V270 | D39: 802BZTE000489 | G39: 26043
A40: ALL IN ONE | B40: LG | C40: 22V270 | D40: 802BZXG000330 | F40: Desativado, no estoque | G40: 31900
...

Sheet Insumos
C2: Lista de Periféricos Distribuido
A4: Tipo do Item | B4: Marca | C4: Responsável | D4: Setor | E4: Data da Entrega do equipamento | F4: Observações
A5: HEADSET | B5: HP | E5: 44901 | F5: Equip. entregue novo
A6: HEADSET | B6: ACER | C6: =_xlfn.CONCAT(Funcionários!B30) -> CAROLINE FOGAÇA DA ROCHA | D6: =_xlfn.CONCAT(Funcionários!C30) -> EXPERIENCIA DAS PESSOAS | E6: 45531 | F6: Equip. entregue novo
A7: HEADSET | B7: HP | C7: =_xlfn.CONCAT(Funcionários!B40) -> ANA LUIZA MATTIA DE LIMA | D7: =_xlfn.CONCAT(Funcionários!C40) -> INTELIGENCIA DE DADOS | E7: 44901 | F7: Equip. entregue em perfeitas condições / semi novo
A8: HEADSET | B8: HP | C8: =_xlfn.CONCAT(Funcionários!B17) -> LARISSA MAY BACK | D8: =_xlfn.CONCAT(Setor!B8) -> FINANCEIRO | E8: 44769 | F8: Equip. entregue novo
A9: HEADSET | B9: HP | C9: =_xlfn.CONCAT(Funcionários!B35) -> WILLIAN RIBEIRO DE SOUZA | D9: =_xlfn.CONCAT(Setor!B13) -> GESTÃO DE FORNECEDORES | E9: 44802 | F9: Equip. entregue novo
A10: HEADSET | B10: FORTEK | E10: 44769 | F10: Desgastado
A11: KIT TECLADO E MOUSE | B11: LOGTECH | C11: =_xlfn.CONCAT(Funcionários!B17) -> LARISSA MAY BACK | D11: =_xlfn.CONCAT(Setor!B8) -> FINANCEIRO | E11: 44770 | F11: Equip. entregue novo
A12: KIT TECLADO E MOUSE | B12: LOGTECH | C12: =_xlfn.CONCAT(Funcionários!B28) -> VANDERLEI MANENTTI SCOTT | D12: =_xlfn.CONCAT(Setor!B16) -> DIRETORIA | E12: 44772 | F12: Equip. entregue novo
A13: KIT TECLADO E MOUSE | B13: LOGTECH | E13: 44833 | F13: Equip. entregue novo
A14: KIT TECLADO E MOUSE | B14: LOGITECH | C14: =_xlfn.CONCAT(Funcionários!B76) -> RUTH MARTINS | D14: =_xlfn.CONCAT(Setor!B8) -> FINANCEIRO | E14: 44774 | F14: Equip. entregue novo
A15: MOUSE | B15: LOGITECH | C15: =_xlfn.CONCAT(Funcionários!B6) -> FELIPE FOLSTER | D15: =_xlfn.CONCAT(Setor!B7) -> INTELIGENCIA DE REDES | E15: 44772 | F15: Equip. entregue novo
A16: KIT TECLADO E MOUSE | B16: LOGITECH | C16: =_xlfn.CONCAT(Funcionários!B21) -> MILENE CRISTINA DA SILVA | D16: =_xlfn.CONCAT(Funcionários!C21) -> FINANCEIRO | E16: 45152 | F16: Equip. entregue novo
A17: KIT TECLADO E MOUSE | B17: LOGITECH | C17: =_xlfn.CONCAT(Funcionários!#REF!) -> #REF! | D17: =_xlfn.CONCAT(Setor!B9) -> COMERCIAL | E17: 44772 | F17: Equip. entregue novo
A18: TECLADO | B18: LOGITECH | C18: =_xlfn.CONCAT(Funcionários!B40) -> ANA LUIZA MATTIA DE LIMA | D18: =_xlfn.CONCAT(Setor!B5) -> RELACIONAMENTO COM O CLIENTE | E18: 45182 | F18: Equip. entregue novo
A19: KIT TECLADO E MOUSE WIRELESS | B19: LOGITECH | C19: =_xlfn.CONCAT(Funcionários!B28) -> VANDERLEI MANENTTI SCOTT | D19: =_xlfn.CONCAT(Setor!B16) -> DIRETORIA | E19: 44804 | F19: Equip. entregue novo
A20: ADAPTADOR RJ45 USB 3.0 | B20: TP LINK | C20: ANDRESSA GUERRA | D20: =_xlfn.CONCAT(Setor!B7) -> INTELIGENCIA DE REDES | E20: 44806 | F20: Equip. entregue novo
A21: ADAPTADOR RJ45 USB 3.0 | B21: TP LINK | C21: =_xlfn.CONCAT(Funcionários!B35) -> WILLIAN RIBEIRO DE SOUZA | D21: =_xlfn.CONCAT(Funcionários!C35) -> GESTÃO DE FORNECEDORES | E21: 44980 | F21: Equip. entregue novo
A22: ADAPTADOR RJ45 USB 3.0 | B22: TP LINK | C22: =_xlfn.CONCAT(Funcionários!B22) -> AMANDA ISSLER NERY | D22: =_xlfn.CONCAT(Funcionários!C22) -> COMERCIAL | E22: 45180 | F22: Equip. entregue usado / Andressa
A23: ADAPTADOR RJ45 USB 3.0 | B23: TP LINK | C23: =_xlfn.CONCAT(Funcionários!B78) -> VINICIUS PLETICOS | D23: =_xlfn.CONCAT(Funcionários!C78) -> RELACIONAMENTO COM O CLIENTE | E23: 44806 | F23: Equip. entregue novo
A24: HEADSET | B24: HP | C24: armario | E24: 44832 | F24: Equip. entregue novo
A25: HEADSET | B25: HP | C25: =_xlfn.CONCAT(Funcionários!B76) -> RUTH MARTINS | D25: =_xlfn.CONCAT(Setor!B8) -> FINANCEIRO | E25: 44827 | F25: Equip. entregue novo
A26: HEADSET | B26: HP | C26: =_xlfn.CONCAT(Funcionários!B24) -> VITOR ADRIANO COELHO | D26: =_xlfn.CONCAT(Funcionários!C24) -> COMERCIAL | E26: 44833 | F26: Equip. entregue novo
A27: HEADSET | B27: HP | C27: =_xlfn.CONCAT(Funcionários!B31) -> LETICIA EMANUELE DE OLIVEIRA | D27: =_xlfn.CONCAT(Funcionários!C31) -> EXPERIENCIA DAS PESSOAS | E27: 44986 | F27: Equip. entregue em perfeitas condições / semi novo
A28: HEADSET | B28: HP | C28: =_xlfn.CONCAT(Funcionários!B49) -> EDUARDA VIEIRA | D28: =_xlfn.CONCAT(Setor!B5) -> RELACIONAMENTO COM O CLIENTE | E28: 44844 | F28: Equip. entregue novo
A29: KIT TECLADO E MOUSE | B29: LOGITECH | C29: =_xlfn.CONCAT(Funcionários!B24) -> VITOR ADRIANO COELHO | D29: =_xlfn.CONCAT(Funcionários!C24) -> COMERCIAL | E29: 44860 | F29: Equip. entregue novo
A30: Mouse | B30: LOGITECH | C30: =_xlfn.CONCAT(Funcionários!#REF!) -> #REF! | D30: =_xlfn.CONCAT(Funcionários!C35) -> GESTÃO DE FORNECEDORES | E30: 44858 | F30: Equip. entregue novo
A31: Mouse | B31: LOGITECH | C31: =_xlfn.CONCAT(Funcionários!B35) -> WILLIAN RIBEIRO DE SOUZA | D31: =_xlfn.CONCAT(Funcionários!C35) -> GESTÃO DE FORNECEDORES | E31: 44858 | F31: Equip. entregue novo
A32: Telefone RJ11 | B32: Multilaser | C32: =_xlfn.CONCAT(Funcionários!B69) -> JONIEL CORREA DA SILVA | D32: =_xlfn.CONCAT(Funcionários!C69) -> RELACIONAMENTO COM O CLIENTE | E32: 44873 | F32: Equip. entregue em perfeitas condições / semi novo
A33: Mouse | B33: LOGITECH | C33: =_xlfn.CONCAT(Funcionários!B31) -> LETICIA EMANUELE DE OLIVEIRA | D33: =_xlfn.CONCAT(Funcionários!C31) -> EXPERIENCIA DAS PESSOAS | E33: 44893 | F33: Equip. entregue novo
A34: KIT TECLADO E MOUSE | B34: LOGITECH | C34: =_xlfn.CONCAT(Funcionários!B9) -> LUIZA CUNHA SENA | D34: AGILIDADE | E34: 44893 | F34: Equip. entregue novo
A35: Mouse | B35: LOGITECH | C35: =_xlfn.CONCAT(Funcionários!B40) -> ANA LUIZA MATTIA DE LIMA | D35: =_xlfn.CONCAT(Funcionários!C40) -> INTELIGENCIA DE DADOS | E35: 44893 | F35: Equip. entregue novo
A36: KIT TECLADO E MOUSE WIRELESS | B36: DELL | C36: =_xlfn.CONCAT(Funcionários!B28) -> VANDERLEI MANENTTI SCOTT | D36: CTO | E36: 45492 | F36: Equip. entregue novo
A37: Moue | B37: LOGITECH | C37: =_xlfn.CONCAT(Funcionários!B35) -> WILLIAN RIBEIRO DE SOUZA | D37: =_xlfn.CONCAT(Funcionários!C35) -> GESTÃO DE FORNECEDORES | E37: 44893 | F37: Equip. entregue novo
A38: Mouse | B38: LOGITECH | E38: 44895 | F38: Equip. entregue novo
A39: Mouse | B39: LOGITECH | C39: DEIVID | D39: NOC | E39: 44909 | F39: Equip. entregue novo
A40: Mouse | B40: LOGITECH | E40: 44910 | F40: Equip. entregue novo
A41: Teclado | B41: LOGITECH | C41: =_xlfn.CONCAT(Funcionários!B35) -> WILLIAN RIBEIRO DE SOUZA | D41: =_xlfn.CONCAT(Funcionários!C35) -> GESTÃO DE FORNECEDORES | E41: 45009 | F41: Equip. entregue novo
A42: MOUSE | B42: LOGITECH | C42: =_xlfn.CONCAT(Funcionários!B35) -> WILLIAN RIBEIRO DE SOUZA | D42: =_xlfn.CONCAT(Funcionários!C35) -> GESTÃO DE FORNECEDORES | E42: 44901 | F42: Equip. entregue novo
...

Sheet Controle de Equipamentos Entreg
A2: Controle de Equipamentos entregues
A4: Nome | B4: Data | C4: Equipamento | D4: Marca | E4: Observações
A5: Marcos Vinicius | B5: 45790 | C5: Teclado | D5: Logitech | E5: Equipamento Usado

Sheet Insumos disponiveis
A2: Lista de Periféricos Disponíveis
A4: Tipo do Item | B4: Quantidade | C4: Marca | D4: Modelo | E4: Observações
A5: Headset | B5: 1 | C5: Intelbras headset RJ9 | E5: Equipamento novo
A6: Headset | B6: 0 | C6: HyperX | D6: 1 Orelha
A7: Headset Total | B7: =SUM(B5,B6) -> 1
A9: Monitor | B9: 0
A10: Monitor | B10: 0
A11: Monitor Total | B11: =SUM(B9,B10) -> 0
A13: Suporte para notebook | B13: 13 | C13: GENÉRICO | E13: Equipamento novo
A15: Mouse Novo | B15: 1 | C15: Logitech
A16: Mouse Seminovo | B16: 2 | C16: GENÉRICO
A17: Mouse Total | B17: =SUM(B15,B16) -> 3
A19: Mousepad | B19: 10 | C19: Multilaser | E19: Equipamento novo
A21: Teclado Novo | B21: 1
A22: Teclado Seminovo | B22: 2
A23: Teclado Total | B23: =SUM(B21,B22) -> 3
A25: Notebook
A26: Notebook
A27: Notebook Total | B27: =SUM(B25,B26) -> 0
A29: USB HUB | B29: 1 | C29: GENÉRICO | E29: Equipamento novo
A31: Adptador de rede | B31: 1
